06/20/2021 23:06:02
File "C:\UserC\Anaconda\envs\translator\lib\site-packages\requests\adapters.py", line 516, in send:
 [ConnectionError]
HTTPSConnectionPool(host='translate.google.com', port=443): Max retries exceeded with url: / (Caused by NewConnectionError('<urllib3.connection.HTTPSConnection object at 0x0000027B8F0B21C0>: Failed to establish a new connection: [Errno 11001] getaddrinfo failed'))
-------------------------
06/20/2021 23:06:14
File "C:\UserC\Anaconda\envs\translator\lib\site-packages\requests\adapters.py", line 516, in send:
 [ConnectionError]
HTTPSConnectionPool(host='translate.google.com', port=443): Max retries exceeded with url: / (Caused by NewConnectionError('<urllib3.connection.HTTPSConnection object at 0x0000027B8F0B28E0>: Failed to establish a new connection: [Errno 11001] getaddrinfo failed'))
-------------------------
06/20/2021 23:06:14
File "C:\UserC\Anaconda\envs\translator\lib\site-packages\requests\adapters.py", line 516, in send:
 [ConnectionError]
HTTPSConnectionPool(host='translate.google.com', port=443): Max retries exceeded with url: / (Caused by NewConnectionError('<urllib3.connection.HTTPSConnection object at 0x0000027B8F0B25B0>: Failed to establish a new connection: [Errno 11001] getaddrinfo failed'))
-------------------------
06/20/2021 23:06:16
File "C:\UserC\Anaconda\envs\translator\lib\site-packages\requests\adapters.py", line 516, in send:
 [ConnectionError]
HTTPSConnectionPool(host='translate.google.com', port=443): Max retries exceeded with url: / (Caused by NewConnectionError('<urllib3.connection.HTTPSConnection object at 0x0000027B8F0B2BE0>: Failed to establish a new connection: [Errno 11001] getaddrinfo failed'))
-------------------------
06/20/2021 23:06:25
File "C:\UserC\Anaconda\envs\translator\lib\site-packages\requests\adapters.py", line 516, in send:
 [ConnectionError]
HTTPSConnectionPool(host='translate.google.com', port=443): Max retries exceeded with url: / (Caused by NewConnectionError('<urllib3.connection.HTTPSConnection object at 0x0000027B8F0B2CD0>: Failed to establish a new connection: [Errno 11001] getaddrinfo failed'))
-------------------------
